\title{Kbot Humanoid}

\taxon{skill}

\meta{version}{1.0.0}

\meta{trit}{-1}

\meta{description}{K-Bot humanoid robot platform - hardware specs, MJCF models, and deployment configurations. The flagship K-Scale humanoid robot.}

\subtree{
\title{K-Bot Humanoid Skill}
\p{\strong{Trit}: -1 (MINUS - specification/verification) \strong{Color}: #5B45C2 (Purple) \strong{URI}: skill://kbot-humanoid#5B45C2}

\subtree{
\title{Overview}
\p{K-Bot is K-Scale Labs' flagship humanoid robot platform. This skill covers hardware specifications, MJCF model configurations, and deployment workflows.}
}

\subtree{
\title{Robot Specifications}
\pre{\startverb
┌────────────────────────────────────────────────────────────────┐
│                      K-BOT HUMANOID                            │
├────────────────────────────────────────────────────────────────┤
│                                                                 │
│  Height: ~1.4m                                                 │
│  Weight: ~30kg                                                 │
│  DOF: 20+ joints                                               │
│                                                                 │
│  Actuators:                                                     │
│  ├── Robstride motors (custom driver)                          │
│  ├── Position/velocity/torque control                          │
│  └── ~40 Nm peak torque per joint                              │
│                                                                 │
│  Sensors:                                                       │
│  ├── IMU (6-axis)                                              │
│  ├── Joint encoders                                            │
│  ├── Cameras (RGB)                                             │
│  └── Force sensors (feet)                                      │
│                                                                 │
│  Compute:                                                       │
│  ├── Onboard: Jetson/custom                                    │
│  └── Inference: Policy runs at 50-100 Hz                       │
│                                                                 │
└────────────────────────────────────────────────────────────────┘
\stopverb}
}

\subtree{
\title{MJCF Model}
\pre{\startverb
<!-- kbot.mjcf excerpt -->
<mujoco model="kbot">
  <compiler angle="radian" meshdir="meshes"/>
  
  <default>
    <joint damping="0.5" armature="0.01"/>
    <geom friction="1 0.005 0.001" condim="3"/>
  </default>
  
  <worldbody>
    <body name="torso" pos="0 0 1.0">
      <freejoint name="root"/>
      <geom type="mesh" mesh="torso"/>
      
      <!-- Legs -->
      <body name="hip_l" pos="0 0.1 0">
        <joint name="hip_yaw_l" type="hinge" axis="0 0 1"/>
        <joint name="hip_roll_l" type="hinge" axis="1 0 0"/>
        <joint name="hip_pitch_l" type="hinge" axis="0 1 0"/>
        <!-- ... -->
      </body>
      
      <!-- Arms -->
      <body name="shoulder_l" pos="0 0.2 0.4">
        <joint name="shoulder_pitch_l" type="hinge" axis="0 1 0"/>
        <joint name="shoulder_roll_l" type="hinge" axis="1 0 0"/>
        <!-- ... -->
      </body>
    </body>
  </worldbody>
  
  <actuator>
    <position name="hip_yaw_l_pos" joint="hip_yaw_l" kp="100"/>
    <position name="hip_roll_l_pos" joint="hip_roll_l" kp="100"/>
    <!-- ... -->
  </actuator>
</mujoco>
\stopverb}
}

\subtree{
\title{Deployment Pipeline}
\pre{\startverb
┌─────────────┐    ┌─────────────┐    ┌─────────────┐    ┌─────────────┐
│   KSIM      │───▶│   Policy    │───▶│   KOS       │───▶│   K-Bot     │
│   Training  │    │   Export    │    │   Firmware  │    │   Hardware  │
└─────────────┘    └─────────────┘    └─────────────┘    └─────────────┘
       │                  │                  │                  │
       ▼                  ▼                  ▼                  ▼
   PPO/AMP in        ONNX/JIT           gRPC actuator      Real robot
   MJX sim           conversion         commands            execution
\stopverb}
}

\subtree{
\title{Training with KSIM}
\pre{\startverb
from ksim.robots.kbot import KBotConfig
from ksim import PPOTask

class KBotWalking(PPOTask):
    robot = KBotConfig(
        model_path="kbot-headless.mjcf",
        joint_names=KBotConfig.DEFAULT_JOINTS,
        actuator_config={
            "kp": 100.0,
            "kd": 10.0,
            "torque_limit": 40.0,
        }
    )
\stopverb}
}

\subtree{
\title{GF(3) Triads}
\pre{\startverb
kbot-humanoid (-1) ⊗ kos-firmware (+1) ⊗ mujoco-scenes (0) = 0 ✓
kbot-humanoid (-1) ⊗ topos-generate (+1) ⊗ ksim-gym (0) = 0 ✓
\stopverb}
}

\subtree{
\title{Related Skills}
\ul{
\li{\code{\startverb ksim-rl\stopverb} (-1): RL training for K-Bot}
\li{\code{\startverb kos-firmware\stopverb} (+1): Firmware for K-Bot deployment}
\li{\code{\startverb zeroth-bot\stopverb} (-1): Smaller 3D-printed platform}
\li{\code{\startverb evla-vla\stopverb} (-1): VLA for manipulation tasks}
}
}

\subtree{
\title{References}
\pre{\startverb
@misc{kbot2024,
  title={K-Bot: Open-Source Humanoid Robot Platform},
  author={K-Scale Labs},
  year={2024},
  url={https://github.com/kscalelabs/kbot}
}
\stopverb}
}

\subtree{
\title{SDF Interleaving}
\p{This skill connects to \strong{Software Design for Flexibility} (Hanson & Sussman, 2021):}

\subtree{
\title{Primary Chapter: 10. Adventure Game Example}
\p{\strong{Concepts}: autonomous agent, game, synthesis}
}

\subtree{
\title{GF(3) Balanced Triad}
\pre{\startverb
kbot-humanoid (○) + SDF.Ch10 (+) + [balancer] (−) = 0
\stopverb}

\p{\strong{Skill Trit}: 0 (ERGODIC - coordination)}
}

\subtree{
\title{Connection Pattern}
\p{Adventure games synthesize techniques. This skill integrates multiple patterns.}
}
}
}